2021-09-01 01:49:46,646 INFO    MainThread:16920 [internal.py:wandb_internal():86] W&B internal server running at pid: 16920, started at: 2021-09-01 01:49:46.637443
2021-09-01 01:49:46,648 INFO    WriterThread:16920 [datastore.py:open_for_write():77] open: F:\5th sem project\wandb\run-20210901_014944-2p7ria01\run-2p7ria01.wandb
2021-09-01 01:49:46,649 DEBUG   HandlerThread:16920 [handler.py:handle_request():128] handle_request: check_version
2021-09-01 01:49:46,653 DEBUG   SenderThread:16920 [sender.py:send():182] send: header
2021-09-01 01:49:46,653 DEBUG   SenderThread:16920 [sender.py:send_request():196] send_request: check_version
2021-09-01 01:49:46,664 DEBUG   SenderThread:16920 [sender.py:send():182] send: run
2021-09-01 01:49:49,922 ERROR   SenderThread:16920 [retry.py:__call__():126] Retry attempt failed:
Traceback (most recent call last):
  File "C:\Users\HP\anaconda3\lib\site-packages\urllib3\connection.py", line 169, in _new_conn
    conn = connection.create_connection(
  File "C:\Users\HP\anaconda3\lib\site-packages\urllib3\util\connection.py", line 73, in create_connection
    for res in socket.getaddrinfo(host, port, family, socket.SOCK_STREAM):
  File "C:\Users\HP\anaconda3\lib\socket.py", line 918, in getaddrinfo
    for res in _socket.getaddrinfo(host, port, family, type, proto, flags):
socket.gaierror: [Errno 11001] getaddrinfo failed

During handling of the above exception, another exception occurred:

Traceback (most recent call last):
  File "C:\Users\HP\anaconda3\lib\site-packages\urllib3\connectionpool.py", line 699, in urlopen
    httplib_response = self._make_request(
  File "C:\Users\HP\anaconda3\lib\site-packages\urllib3\connectionpool.py", line 382, in _make_request
    self._validate_conn(conn)
  File "C:\Users\HP\anaconda3\lib\site-packages\urllib3\connectionpool.py", line 1010, in _validate_conn
    conn.connect()
  File "C:\Users\HP\anaconda3\lib\site-packages\urllib3\connection.py", line 353, in connect
    conn = self._new_conn()
  File "C:\Users\HP\anaconda3\lib\site-packages\urllib3\connection.py", line 181, in _new_conn
    raise NewConnectionError(
urllib3.exceptions.NewConnectionError: <urllib3.connection.HTTPSConnection object at 0x000001F71318A6A0>: Failed to establish a new connection: [Errno 11001] getaddrinfo failed

During handling of the above exception, another exception occurred:

Traceback (most recent call last):
  File "C:\Users\HP\anaconda3\lib\site-packages\requests\adapters.py", line 439, in send
    resp = conn.urlopen(
  File "C:\Users\HP\anaconda3\lib\site-packages\urllib3\connectionpool.py", line 755, in urlopen
    retries = retries.increment(
  File "C:\Users\HP\anaconda3\lib\site-packages\urllib3\util\retry.py", line 574, in increment
    raise MaxRetryError(_pool, url, error or ResponseError(cause))
urllib3.exceptions.MaxRetryError: HTTPSConnectionPool(host='api.wandb.ai', port=443): Max retries exceeded with url: /graphql (Caused by NewConnectionError('<urllib3.connection.HTTPSConnection object at 0x000001F71318A6A0>: Failed to establish a new connection: [Errno 11001] getaddrinfo failed'))

During handling of the above exception, another exception occurred:

Traceback (most recent call last):
  File "C:\Users\HP\anaconda3\lib\site-packages\wandb\sdk\lib\retry.py", line 102, in __call__
    result = self._call_fn(*args, **kwargs)
  File "C:\Users\HP\anaconda3\lib\site-packages\wandb\sdk\internal\internal_api.py", line 130, in execute
    return self.client.execute(*args, **kwargs)
  File "C:\Users\HP\anaconda3\lib\site-packages\wandb\vendor\gql-0.2.0\gql\client.py", line 52, in execute
    result = self._get_result(document, *args, **kwargs)
  File "C:\Users\HP\anaconda3\lib\site-packages\wandb\vendor\gql-0.2.0\gql\client.py", line 60, in _get_result
    return self.transport.execute(document, *args, **kwargs)
  File "C:\Users\HP\anaconda3\lib\site-packages\wandb\vendor\gql-0.2.0\gql\transport\requests.py", line 38, in execute
    request = requests.post(self.url, **post_args)
  File "C:\Users\HP\anaconda3\lib\site-packages\requests\api.py", line 119, in post
    return request('post', url, data=data, json=json, **kwargs)
  File "C:\Users\HP\anaconda3\lib\site-packages\requests\api.py", line 61, in request
    return session.request(method=method, url=url, **kwargs)
  File "C:\Users\HP\anaconda3\lib\site-packages\requests\sessions.py", line 542, in request
    resp = self.send(prep, **send_kwargs)
  File "C:\Users\HP\anaconda3\lib\site-packages\requests\sessions.py", line 655, in send
    r = adapter.send(request, **kwargs)
  File "C:\Users\HP\anaconda3\lib\site-packages\requests\adapters.py", line 516, in send
    raise ConnectionError(e, request=request)
requests.exceptions.ConnectionError: HTTPSConnectionPool(host='api.wandb.ai', port=443): Max retries exceeded with url: /graphql (Caused by NewConnectionError('<urllib3.connection.HTTPSConnection object at 0x000001F71318A6A0>: Failed to establish a new connection: [Errno 11001] getaddrinfo failed'))
2021-09-01 01:50:16,664 DEBUG   HandlerThread:16920 [handler.py:handle_request():128] handle_request: shutdown
2021-09-01 01:50:16,664 INFO    HandlerThread:16920 [handler.py:finish():677] shutting down handler
2021-09-01 01:50:16,676 INFO    WriterThread:16920 [datastore.py:close():281] close: F:\5th sem project\wandb\run-20210901_014944-2p7ria01\run-2p7ria01.wandb
2021-09-01 01:52:12,799 INFO    SenderThread:16920 [dir_watcher.py:__init__():168] watching files in: F:\5th sem project\wandb\run-20210901_014944-2p7ria01\files
2021-09-01 01:52:12,799 INFO    SenderThread:16920 [sender.py:_start_run_threads():740] run started: 2p7ria01 with start time 1630441184
2021-09-01 01:52:12,799 INFO    SenderThread:16920 [sender.py:finish():979] shutting down sender
2021-09-01 01:52:12,799 INFO    SenderThread:16920 [dir_watcher.py:finish():282] shutting down directory watcher
2021-09-01 01:52:13,800 INFO    SenderThread:16920 [dir_watcher.py:finish():312] scan: F:\5th sem project\wandb\run-20210901_014944-2p7ria01\files
2021-09-01 01:52:13,800 INFO    SenderThread:16920 [dir_watcher.py:finish():318] scan save: F:\5th sem project\wandb\run-20210901_014944-2p7ria01\files\config.yaml config.yaml
2021-09-01 01:52:13,801 INFO    SenderThread:16920 [file_pusher.py:finish():177] shutting down file pusher
2021-09-01 01:52:13,801 INFO    SenderThread:16920 [file_pusher.py:join():182] waiting for file pusher
2021-09-01 01:52:15,193 INFO    Thread-10 :16920 [upload_job.py:push():137] Uploaded file F:\5th sem project\wandb\run-20210901_014944-2p7ria01\files\config.yaml
2021-09-01 01:52:16,386 INFO    MainThread:16920 [internal.py:handle_exit():76] Internal process exited
