2021-09-15 18:06:04,655 INFO    MainThread:8500 [internal.py:wandb_internal():86] W&B internal server running at pid: 8500, started at: 2021-09-15 18:06:04.647007
2021-09-15 18:06:04,656 INFO    WriterThread:8500 [datastore.py:open_for_write():77] open: F:\5th sem project\wandb\run-20210915_180602-14jvonpv\run-14jvonpv.wandb
2021-09-15 18:06:04,656 DEBUG   HandlerThread:8500 [handler.py:handle_request():126] handle_request: check_version
2021-09-15 18:06:04,660 DEBUG   SenderThread:8500 [sender.py:send():182] send: header
2021-09-15 18:06:04,660 DEBUG   SenderThread:8500 [sender.py:send_request():196] send_request: check_version
2021-09-15 18:06:04,671 DEBUG   SenderThread:8500 [sender.py:send():182] send: run
2021-09-15 18:06:08,119 ERROR   SenderThread:8500 [retry.py:__call__():126] Retry attempt failed:
Traceback (most recent call last):
  File "C:\Users\HP\anaconda3\lib\site-packages\urllib3\connection.py", line 169, in _new_conn
    conn = connection.create_connection(
  File "C:\Users\HP\anaconda3\lib\site-packages\urllib3\util\connection.py", line 73, in create_connection
    for res in socket.getaddrinfo(host, port, family, socket.SOCK_STREAM):
  File "C:\Users\HP\anaconda3\lib\socket.py", line 918, in getaddrinfo
    for res in _socket.getaddrinfo(host, port, family, type, proto, flags):
socket.gaierror: [Errno 11001] getaddrinfo failed

During handling of the above exception, another exception occurred:

Traceback (most recent call last):
  File "C:\Users\HP\anaconda3\lib\site-packages\urllib3\connectionpool.py", line 699, in urlopen
    httplib_response = self._make_request(
  File "C:\Users\HP\anaconda3\lib\site-packages\urllib3\connectionpool.py", line 382, in _make_request
    self._validate_conn(conn)
  File "C:\Users\HP\anaconda3\lib\site-packages\urllib3\connectionpool.py", line 1010, in _validate_conn
    conn.connect()
  File "C:\Users\HP\anaconda3\lib\site-packages\urllib3\connection.py", line 353, in connect
    conn = self._new_conn()
  File "C:\Users\HP\anaconda3\lib\site-packages\urllib3\connection.py", line 181, in _new_conn
    raise NewConnectionError(
urllib3.exceptions.NewConnectionError: <urllib3.connection.HTTPSConnection object at 0x000001E32C19C1F0>: Failed to establish a new connection: [Errno 11001] getaddrinfo failed

During handling of the above exception, another exception occurred:

Traceback (most recent call last):
  File "C:\Users\HP\anaconda3\lib\site-packages\requests\adapters.py", line 439, in send
    resp = conn.urlopen(
  File "C:\Users\HP\anaconda3\lib\site-packages\urllib3\connectionpool.py", line 755, in urlopen
    retries = retries.increment(
  File "C:\Users\HP\anaconda3\lib\site-packages\urllib3\util\retry.py", line 574, in increment
    raise MaxRetryError(_pool, url, error or ResponseError(cause))
urllib3.exceptions.MaxRetryError: HTTPSConnectionPool(host='api.wandb.ai', port=443): Max retries exceeded with url: /graphql (Caused by NewConnectionError('<urllib3.connection.HTTPSConnection object at 0x000001E32C19C1F0>: Failed to establish a new connection: [Errno 11001] getaddrinfo failed'))

During handling of the above exception, another exception occurred:

Traceback (most recent call last):
  File "C:\Users\HP\anaconda3\lib\site-packages\wandb\sdk\lib\retry.py", line 102, in __call__
    result = self._call_fn(*args, **kwargs)
  File "C:\Users\HP\anaconda3\lib\site-packages\wandb\sdk\internal\internal_api.py", line 130, in execute
    return self.client.execute(*args, **kwargs)
  File "C:\Users\HP\anaconda3\lib\site-packages\wandb\vendor\gql-0.2.0\gql\client.py", line 52, in execute
    result = self._get_result(document, *args, **kwargs)
  File "C:\Users\HP\anaconda3\lib\site-packages\wandb\vendor\gql-0.2.0\gql\client.py", line 60, in _get_result
    return self.transport.execute(document, *args, **kwargs)
  File "C:\Users\HP\anaconda3\lib\site-packages\wandb\vendor\gql-0.2.0\gql\transport\requests.py", line 38, in execute
    request = requests.post(self.url, **post_args)
  File "C:\Users\HP\anaconda3\lib\site-packages\requests\api.py", line 117, in post
    return request('post', url, data=data, json=json, **kwargs)
  File "C:\Users\HP\anaconda3\lib\site-packages\requests\api.py", line 61, in request
    return session.request(method=method, url=url, **kwargs)
  File "C:\Users\HP\anaconda3\lib\site-packages\requests\sessions.py", line 542, in request
    resp = self.send(prep, **send_kwargs)
  File "C:\Users\HP\anaconda3\lib\site-packages\requests\sessions.py", line 655, in send
    r = adapter.send(request, **kwargs)
  File "C:\Users\HP\anaconda3\lib\site-packages\requests\adapters.py", line 516, in send
    raise ConnectionError(e, request=request)
requests.exceptions.ConnectionError: HTTPSConnectionPool(host='api.wandb.ai', port=443): Max retries exceeded with url: /graphql (Caused by NewConnectionError('<urllib3.connection.HTTPSConnection object at 0x000001E32C19C1F0>: Failed to establish a new connection: [Errno 11001] getaddrinfo failed'))
2021-09-15 18:06:29,675 WARNING MainThread:8500 [internal.py:is_dead():364] Internal process exiting, parent pid 16684 disappeared
2021-09-15 18:06:29,675 ERROR   MainThread:8500 [internal.py:wandb_internal():141] Internal process shutdown.
2021-09-15 18:06:29,683 INFO    WriterThread:8500 [datastore.py:close():281] close: F:\5th sem project\wandb\run-20210915_180602-14jvonpv\run-14jvonpv.wandb
2021-09-15 18:06:29,684 INFO    HandlerThread:8500 [handler.py:finish():683] shutting down handler
2021-09-15 18:06:29,827 INFO    SenderThread:8500 [dir_watcher.py:__init__():169] watching files in: F:\5th sem project\wandb\run-20210915_180602-14jvonpv\files
2021-09-15 18:06:29,828 INFO    SenderThread:8500 [sender.py:_start_run_threads():740] run started: 14jvonpv with start time 1631709363
2021-09-15 18:06:29,828 INFO    SenderThread:8500 [sender.py:finish():979] shutting down sender
2021-09-15 18:06:29,828 INFO    SenderThread:8500 [dir_watcher.py:finish():283] shutting down directory watcher
2021-09-15 18:06:30,827 INFO    SenderThread:8500 [dir_watcher.py:finish():313] scan: F:\5th sem project\wandb\run-20210915_180602-14jvonpv\files
2021-09-15 18:06:30,828 INFO    SenderThread:8500 [dir_watcher.py:finish():327] scan save: F:\5th sem project\wandb\run-20210915_180602-14jvonpv\files\config.yaml config.yaml
2021-09-15 18:06:30,829 INFO    SenderThread:8500 [file_pusher.py:finish():177] shutting down file pusher
2021-09-15 18:06:30,829 INFO    SenderThread:8500 [file_pusher.py:join():182] waiting for file pusher
2021-09-15 18:06:32,709 INFO    Thread-10 :8500 [upload_job.py:push():137] Uploaded file F:\5th sem project\wandb\run-20210915_180602-14jvonpv\files\config.yaml
2021-09-15 18:06:33,823 WARNING FileStreamThread:8500 [file_stream.py:request_with_retry():461] requests_with_retry encountered retryable exception: ('Connection aborted.', OSError(10051, 'A socket operation was attempted to an unreachable network', None, 10051, None)). func: <bound method Session.post of <requests.sessions.Session object at 0x000001E32C1BD130>>, args: ('https://api.wandb.ai/files/khushal/last-weather-recognization/14jvonpv/file_stream',), kwargs: {'json': {'complete': True, 'exitcode': 0, 'dropped': 0, 'uploaded': ['config.yaml']}}
2021-09-15 18:06:35,955 WARNING FileStreamThread:8500 [file_stream.py:request_with_retry():461] requests_with_retry encountered retryable exception: HTTPSConnectionPool(host='api.wandb.ai', port=443): Max retries exceeded with url: /files/khushal/last-weather-recognization/14jvonpv/file_stream (Caused by NewConnectionError('<urllib3.connection.HTTPSConnection object at 0x000001E32C186EE0>: Failed to establish a new connection: [Errno 11001] getaddrinfo failed')). func: <bound method Session.post of <requests.sessions.Session object at 0x000001E32C1BD130>>, args: ('https://api.wandb.ai/files/khushal/last-weather-recognization/14jvonpv/file_stream',), kwargs: {'json': {'complete': True, 'exitcode': 0, 'dropped': 0, 'uploaded': ['config.yaml']}}
2021-09-15 18:06:40,162 WARNING FileStreamThread:8500 [file_stream.py:request_with_retry():461] requests_with_retry encountered retryable exception: HTTPSConnectionPool(host='api.wandb.ai', port=443): Max retries exceeded with url: /files/khushal/last-weather-recognization/14jvonpv/file_stream (Caused by NewConnectionError('<urllib3.connection.HTTPSConnection object at 0x000001E32C186D90>: Failed to establish a new connection: [Errno 11001] getaddrinfo failed')). func: <bound method Session.post of <requests.sessions.Session object at 0x000001E32C1BD130>>, args: ('https://api.wandb.ai/files/khushal/last-weather-recognization/14jvonpv/file_stream',), kwargs: {'json': {'complete': True, 'exitcode': 0, 'dropped': 0, 'uploaded': ['config.yaml']}}
2021-09-15 18:06:49,935 WARNING FileStreamThread:8500 [file_stream.py:request_with_retry():461] requests_with_retry encountered retryable exception: HTTPSConnectionPool(host='api.wandb.ai', port=443): Max retries exceeded with url: /files/khushal/last-weather-recognization/14jvonpv/file_stream (Caused by NewConnectionError('<urllib3.connection.HTTPSConnection object at 0x000001E32C186EE0>: Failed to establish a new connection: [Errno 11001] getaddrinfo failed')). func: <bound method Session.post of <requests.sessions.Session object at 0x000001E32C1BD130>>, args: ('https://api.wandb.ai/files/khushal/last-weather-recognization/14jvonpv/file_stream',), kwargs: {'json': {'complete': True, 'exitcode': 0, 'dropped': 0, 'uploaded': ['config.yaml']}}
2021-09-15 18:07:10,070 INFO    MainThread:8500 [internal.py:handle_exit():76] Internal process exited
