2021-08-23 17:14:49,663 INFO    MainThread:17648 [internal.py:wandb_internal():86] W&B internal server running at pid: 17648, started at: 2021-08-23 17:14:49.640971
2021-08-23 17:14:49,668 INFO    WriterThread:17648 [datastore.py:open_for_write():77] open: F:\5th sem project\wandb\run-20210823_171444-1805fxh5\run-1805fxh5.wandb
2021-08-23 17:14:49,669 DEBUG   HandlerThread:17648 [handler.py:handle_request():128] handle_request: check_version
2021-08-23 17:14:49,678 DEBUG   SenderThread:17648 [sender.py:send():182] send: header
2021-08-23 17:14:49,678 DEBUG   SenderThread:17648 [sender.py:send_request():196] send_request: check_version
2021-08-23 17:14:49,699 DEBUG   SenderThread:17648 [sender.py:send():182] send: run
2021-08-23 17:14:53,158 ERROR   SenderThread:17648 [retry.py:__call__():126] Retry attempt failed:
Traceback (most recent call last):
  File "C:\Users\HP\anaconda3\lib\site-packages\urllib3\connection.py", line 169, in _new_conn
    conn = connection.create_connection(
  File "C:\Users\HP\anaconda3\lib\site-packages\urllib3\util\connection.py", line 73, in create_connection
    for res in socket.getaddrinfo(host, port, family, socket.SOCK_STREAM):
  File "C:\Users\HP\anaconda3\lib\socket.py", line 918, in getaddrinfo
    for res in _socket.getaddrinfo(host, port, family, type, proto, flags):
socket.gaierror: [Errno 11001] getaddrinfo failed

During handling of the above exception, another exception occurred:

Traceback (most recent call last):
  File "C:\Users\HP\anaconda3\lib\site-packages\urllib3\connectionpool.py", line 699, in urlopen
    httplib_response = self._make_request(
  File "C:\Users\HP\anaconda3\lib\site-packages\urllib3\connectionpool.py", line 382, in _make_request
    self._validate_conn(conn)
  File "C:\Users\HP\anaconda3\lib\site-packages\urllib3\connectionpool.py", line 1010, in _validate_conn
    conn.connect()
  File "C:\Users\HP\anaconda3\lib\site-packages\urllib3\connection.py", line 353, in connect
    conn = self._new_conn()
  File "C:\Users\HP\anaconda3\lib\site-packages\urllib3\connection.py", line 181, in _new_conn
    raise NewConnectionError(
urllib3.exceptions.NewConnectionError: <urllib3.connection.HTTPSConnection object at 0x00000261406357F0>: Failed to establish a new connection: [Errno 11001] getaddrinfo failed

During handling of the above exception, another exception occurred:

Traceback (most recent call last):
  File "C:\Users\HP\anaconda3\lib\site-packages\requests\adapters.py", line 439, in send
    resp = conn.urlopen(
  File "C:\Users\HP\anaconda3\lib\site-packages\urllib3\connectionpool.py", line 755, in urlopen
    retries = retries.increment(
  File "C:\Users\HP\anaconda3\lib\site-packages\urllib3\util\retry.py", line 574, in increment
    raise MaxRetryError(_pool, url, error or ResponseError(cause))
urllib3.exceptions.MaxRetryError: HTTPSConnectionPool(host='api.wandb.ai', port=443): Max retries exceeded with url: /graphql (Caused by NewConnectionError('<urllib3.connection.HTTPSConnection object at 0x00000261406357F0>: Failed to establish a new connection: [Errno 11001] getaddrinfo failed'))

During handling of the above exception, another exception occurred:

Traceback (most recent call last):
  File "C:\Users\HP\anaconda3\lib\site-packages\wandb\sdk\lib\retry.py", line 102, in __call__
    result = self._call_fn(*args, **kwargs)
  File "C:\Users\HP\anaconda3\lib\site-packages\wandb\sdk\internal\internal_api.py", line 130, in execute
    return self.client.execute(*args, **kwargs)
  File "C:\Users\HP\anaconda3\lib\site-packages\wandb\vendor\gql-0.2.0\gql\client.py", line 52, in execute
    result = self._get_result(document, *args, **kwargs)
  File "C:\Users\HP\anaconda3\lib\site-packages\wandb\vendor\gql-0.2.0\gql\client.py", line 60, in _get_result
    return self.transport.execute(document, *args, **kwargs)
  File "C:\Users\HP\anaconda3\lib\site-packages\wandb\vendor\gql-0.2.0\gql\transport\requests.py", line 38, in execute
    request = requests.post(self.url, **post_args)
  File "C:\Users\HP\anaconda3\lib\site-packages\requests\api.py", line 119, in post
    return request('post', url, data=data, json=json, **kwargs)
  File "C:\Users\HP\anaconda3\lib\site-packages\requests\api.py", line 61, in request
    return session.request(method=method, url=url, **kwargs)
  File "C:\Users\HP\anaconda3\lib\site-packages\requests\sessions.py", line 542, in request
    resp = self.send(prep, **send_kwargs)
  File "C:\Users\HP\anaconda3\lib\site-packages\requests\sessions.py", line 655, in send
    r = adapter.send(request, **kwargs)
  File "C:\Users\HP\anaconda3\lib\site-packages\requests\adapters.py", line 516, in send
    raise ConnectionError(e, request=request)
requests.exceptions.ConnectionError: HTTPSConnectionPool(host='api.wandb.ai', port=443): Max retries exceeded with url: /graphql (Caused by NewConnectionError('<urllib3.connection.HTTPSConnection object at 0x00000261406357F0>: Failed to establish a new connection: [Errno 11001] getaddrinfo failed'))
2021-08-23 17:15:19,680 DEBUG   HandlerThread:17648 [handler.py:handle_request():128] handle_request: shutdown
2021-08-23 17:15:19,681 INFO    HandlerThread:17648 [handler.py:finish():677] shutting down handler
2021-08-23 17:15:19,695 INFO    WriterThread:17648 [datastore.py:close():281] close: F:\5th sem project\wandb\run-20210823_171444-1805fxh5\run-1805fxh5.wandb
2021-08-23 17:16:03,658 INFO    SenderThread:17648 [dir_watcher.py:__init__():168] watching files in: F:\5th sem project\wandb\run-20210823_171444-1805fxh5\files
2021-08-23 17:16:03,658 INFO    SenderThread:17648 [sender.py:_start_run_threads():740] run started: 1805fxh5 with start time 1629719084
2021-08-23 17:16:03,658 INFO    SenderThread:17648 [sender.py:finish():979] shutting down sender
2021-08-23 17:16:03,659 INFO    SenderThread:17648 [dir_watcher.py:finish():282] shutting down directory watcher
2021-08-23 17:16:04,658 INFO    SenderThread:17648 [dir_watcher.py:finish():312] scan: F:\5th sem project\wandb\run-20210823_171444-1805fxh5\files
2021-08-23 17:16:04,659 INFO    SenderThread:17648 [dir_watcher.py:finish():318] scan save: F:\5th sem project\wandb\run-20210823_171444-1805fxh5\files\config.yaml config.yaml
2021-08-23 17:16:04,736 INFO    SenderThread:17648 [file_pusher.py:finish():177] shutting down file pusher
2021-08-23 17:16:04,737 INFO    SenderThread:17648 [file_pusher.py:join():182] waiting for file pusher
2021-08-23 17:16:07,820 INFO    Thread-10 :17648 [upload_job.py:push():137] Uploaded file F:\5th sem project\wandb\run-20210823_171444-1805fxh5\files\config.yaml
2021-08-23 17:16:09,131 INFO    MainThread:17648 [internal.py:handle_exit():76] Internal process exited
