2021-08-26 19:52:10,952 INFO    MainThread:12988 [internal.py:wandb_internal():86] W&B internal server running at pid: 12988, started at: 2021-08-26 19:52:10.943003
2021-08-26 19:52:10,954 INFO    WriterThread:12988 [datastore.py:open_for_write():77] open: F:\5th sem project\wandb\run-20210826_195208-6q3b3bbk\run-6q3b3bbk.wandb
2021-08-26 19:52:10,955 DEBUG   HandlerThread:12988 [handler.py:handle_request():128] handle_request: check_version
2021-08-26 19:52:10,959 DEBUG   SenderThread:12988 [sender.py:send():182] send: header
2021-08-26 19:52:10,960 DEBUG   SenderThread:12988 [sender.py:send_request():196] send_request: check_version
2021-08-26 19:52:14,425 DEBUG   SenderThread:12988 [sender.py:send():182] send: run
2021-08-26 19:52:43,659 DEBUG   HandlerThread:12988 [handler.py:handle_request():128] handle_request: shutdown
2021-08-26 19:52:43,659 INFO    HandlerThread:12988 [handler.py:finish():677] shutting down handler
2021-08-26 19:52:43,672 INFO    WriterThread:12988 [datastore.py:close():281] close: F:\5th sem project\wandb\run-20210826_195208-6q3b3bbk\run-6q3b3bbk.wandb
2021-08-26 19:52:47,966 ERROR   SenderThread:12988 [retry.py:__call__():126] Retry attempt failed:
Traceback (most recent call last):
  File "C:\Users\HP\anaconda3\lib\site-packages\urllib3\connectionpool.py", line 382, in _make_request
    self._validate_conn(conn)
  File "C:\Users\HP\anaconda3\lib\site-packages\urllib3\connectionpool.py", line 1010, in _validate_conn
    conn.connect()
  File "C:\Users\HP\anaconda3\lib\site-packages\urllib3\connection.py", line 411, in connect
    self.sock = ssl_wrap_socket(
  File "C:\Users\HP\anaconda3\lib\site-packages\urllib3\util\ssl_.py", line 449, in ssl_wrap_socket
    ssl_sock = _ssl_wrap_socket_impl(
  File "C:\Users\HP\anaconda3\lib\site-packages\urllib3\util\ssl_.py", line 493, in _ssl_wrap_socket_impl
    return ssl_context.wrap_socket(sock, server_hostname=server_hostname)
  File "C:\Users\HP\anaconda3\lib\ssl.py", line 500, in wrap_socket
    return self.sslsocket_class._create(
  File "C:\Users\HP\anaconda3\lib\ssl.py", line 1040, in _create
    self.do_handshake()
  File "C:\Users\HP\anaconda3\lib\ssl.py", line 1309, in do_handshake
    self._sslobj.do_handshake()
socket.timeout: _ssl.c:1114: The handshake operation timed out

During handling of the above exception, another exception occurred:

Traceback (most recent call last):
  File "C:\Users\HP\anaconda3\lib\site-packages\requests\adapters.py", line 439, in send
    resp = conn.urlopen(
  File "C:\Users\HP\anaconda3\lib\site-packages\urllib3\connectionpool.py", line 755, in urlopen
    retries = retries.increment(
  File "C:\Users\HP\anaconda3\lib\site-packages\urllib3\util\retry.py", line 532, in increment
    raise six.reraise(type(error), error, _stacktrace)
  File "C:\Users\HP\anaconda3\lib\site-packages\urllib3\packages\six.py", line 770, in reraise
    raise value
  File "C:\Users\HP\anaconda3\lib\site-packages\urllib3\connectionpool.py", line 699, in urlopen
    httplib_response = self._make_request(
  File "C:\Users\HP\anaconda3\lib\site-packages\urllib3\connectionpool.py", line 385, in _make_request
    self._raise_timeout(err=e, url=url, timeout_value=conn.timeout)
  File "C:\Users\HP\anaconda3\lib\site-packages\urllib3\connectionpool.py", line 336, in _raise_timeout
    raise ReadTimeoutError(
urllib3.exceptions.ReadTimeoutError: HTTPSConnectionPool(host='api.wandb.ai', port=443): Read timed out. (read timeout=10)

During handling of the above exception, another exception occurred:

Traceback (most recent call last):
  File "C:\Users\HP\anaconda3\lib\site-packages\wandb\sdk\lib\retry.py", line 102, in __call__
    result = self._call_fn(*args, **kwargs)
  File "C:\Users\HP\anaconda3\lib\site-packages\wandb\sdk\internal\internal_api.py", line 130, in execute
    return self.client.execute(*args, **kwargs)
  File "C:\Users\HP\anaconda3\lib\site-packages\wandb\vendor\gql-0.2.0\gql\client.py", line 52, in execute
    result = self._get_result(document, *args, **kwargs)
  File "C:\Users\HP\anaconda3\lib\site-packages\wandb\vendor\gql-0.2.0\gql\client.py", line 60, in _get_result
    return self.transport.execute(document, *args, **kwargs)
  File "C:\Users\HP\anaconda3\lib\site-packages\wandb\vendor\gql-0.2.0\gql\transport\requests.py", line 38, in execute
    request = requests.post(self.url, **post_args)
  File "C:\Users\HP\anaconda3\lib\site-packages\requests\api.py", line 119, in post
    return request('post', url, data=data, json=json, **kwargs)
  File "C:\Users\HP\anaconda3\lib\site-packages\requests\api.py", line 61, in request
    return session.request(method=method, url=url, **kwargs)
  File "C:\Users\HP\anaconda3\lib\site-packages\requests\sessions.py", line 542, in request
    resp = self.send(prep, **send_kwargs)
  File "C:\Users\HP\anaconda3\lib\site-packages\requests\sessions.py", line 655, in send
    r = adapter.send(request, **kwargs)
  File "C:\Users\HP\anaconda3\lib\site-packages\requests\adapters.py", line 529, in send
    raise ReadTimeout(e, request=request)
requests.exceptions.ReadTimeout: HTTPSConnectionPool(host='api.wandb.ai', port=443): Read timed out. (read timeout=10)
2021-08-26 19:58:09,866 INFO    SenderThread:12988 [dir_watcher.py:__init__():168] watching files in: F:\5th sem project\wandb\run-20210826_195208-6q3b3bbk\files
2021-08-26 19:58:09,866 INFO    SenderThread:12988 [sender.py:_start_run_threads():740] run started: 6q3b3bbk with start time 1629987728
2021-08-26 19:58:09,866 INFO    SenderThread:12988 [sender.py:finish():979] shutting down sender
2021-08-26 19:58:09,866 INFO    SenderThread:12988 [dir_watcher.py:finish():282] shutting down directory watcher
2021-08-26 19:58:10,866 INFO    SenderThread:12988 [dir_watcher.py:finish():312] scan: F:\5th sem project\wandb\run-20210826_195208-6q3b3bbk\files
2021-08-26 19:58:10,867 INFO    SenderThread:12988 [dir_watcher.py:finish():318] scan save: F:\5th sem project\wandb\run-20210826_195208-6q3b3bbk\files\config.yaml config.yaml
2021-08-26 19:58:10,867 INFO    SenderThread:12988 [file_pusher.py:finish():177] shutting down file pusher
2021-08-26 19:58:10,867 INFO    SenderThread:12988 [file_pusher.py:join():182] waiting for file pusher
2021-08-26 19:58:12,165 INFO    Thread-10 :12988 [upload_job.py:push():137] Uploaded file F:\5th sem project\wandb\run-20210826_195208-6q3b3bbk\files\config.yaml
2021-08-26 19:58:12,881 INFO    MainThread:12988 [internal.py:handle_exit():76] Internal process exited
