2021-09-15 18:04:16,908 INFO    MainThread:6500 [internal.py:wandb_internal():86] W&B internal server running at pid: 6500, started at: 2021-09-15 18:04:16.900142
2021-09-15 18:04:16,910 INFO    WriterThread:6500 [datastore.py:open_for_write():77] open: F:\5th sem project\wandb\run-20210915_180410-3jtn7q86\run-3jtn7q86.wandb
2021-09-15 18:04:16,910 DEBUG   HandlerThread:6500 [handler.py:handle_request():126] handle_request: check_version
2021-09-15 18:04:16,915 DEBUG   SenderThread:6500 [sender.py:send():182] send: header
2021-09-15 18:04:16,915 DEBUG   SenderThread:6500 [sender.py:send_request():196] send_request: check_version
2021-09-15 18:04:16,925 DEBUG   SenderThread:6500 [sender.py:send():182] send: run
2021-09-15 18:04:20,316 ERROR   SenderThread:6500 [retry.py:__call__():126] Retry attempt failed:
Traceback (most recent call last):
  File "C:\Users\HP\anaconda3\lib\site-packages\urllib3\connection.py", line 169, in _new_conn
    conn = connection.create_connection(
  File "C:\Users\HP\anaconda3\lib\site-packages\urllib3\util\connection.py", line 73, in create_connection
    for res in socket.getaddrinfo(host, port, family, socket.SOCK_STREAM):
  File "C:\Users\HP\anaconda3\lib\socket.py", line 918, in getaddrinfo
    for res in _socket.getaddrinfo(host, port, family, type, proto, flags):
socket.gaierror: [Errno 11001] getaddrinfo failed

During handling of the above exception, another exception occurred:

Traceback (most recent call last):
  File "C:\Users\HP\anaconda3\lib\site-packages\urllib3\connectionpool.py", line 699, in urlopen
    httplib_response = self._make_request(
  File "C:\Users\HP\anaconda3\lib\site-packages\urllib3\connectionpool.py", line 382, in _make_request
    self._validate_conn(conn)
  File "C:\Users\HP\anaconda3\lib\site-packages\urllib3\connectionpool.py", line 1010, in _validate_conn
    conn.connect()
  File "C:\Users\HP\anaconda3\lib\site-packages\urllib3\connection.py", line 353, in connect
    conn = self._new_conn()
  File "C:\Users\HP\anaconda3\lib\site-packages\urllib3\connection.py", line 181, in _new_conn
    raise NewConnectionError(
urllib3.exceptions.NewConnectionError: <urllib3.connection.HTTPSConnection object at 0x00000233B08CF220>: Failed to establish a new connection: [Errno 11001] getaddrinfo failed

During handling of the above exception, another exception occurred:

Traceback (most recent call last):
  File "C:\Users\HP\anaconda3\lib\site-packages\requests\adapters.py", line 439, in send
    resp = conn.urlopen(
  File "C:\Users\HP\anaconda3\lib\site-packages\urllib3\connectionpool.py", line 755, in urlopen
    retries = retries.increment(
  File "C:\Users\HP\anaconda3\lib\site-packages\urllib3\util\retry.py", line 574, in increment
    raise MaxRetryError(_pool, url, error or ResponseError(cause))
urllib3.exceptions.MaxRetryError: HTTPSConnectionPool(host='api.wandb.ai', port=443): Max retries exceeded with url: /graphql (Caused by NewConnectionError('<urllib3.connection.HTTPSConnection object at 0x00000233B08CF220>: Failed to establish a new connection: [Errno 11001] getaddrinfo failed'))

During handling of the above exception, another exception occurred:

Traceback (most recent call last):
  File "C:\Users\HP\anaconda3\lib\site-packages\wandb\sdk\lib\retry.py", line 102, in __call__
    result = self._call_fn(*args, **kwargs)
  File "C:\Users\HP\anaconda3\lib\site-packages\wandb\sdk\internal\internal_api.py", line 130, in execute
    return self.client.execute(*args, **kwargs)
  File "C:\Users\HP\anaconda3\lib\site-packages\wandb\vendor\gql-0.2.0\gql\client.py", line 52, in execute
    result = self._get_result(document, *args, **kwargs)
  File "C:\Users\HP\anaconda3\lib\site-packages\wandb\vendor\gql-0.2.0\gql\client.py", line 60, in _get_result
    return self.transport.execute(document, *args, **kwargs)
  File "C:\Users\HP\anaconda3\lib\site-packages\wandb\vendor\gql-0.2.0\gql\transport\requests.py", line 38, in execute
    request = requests.post(self.url, **post_args)
  File "C:\Users\HP\anaconda3\lib\site-packages\requests\api.py", line 117, in post
    return request('post', url, data=data, json=json, **kwargs)
  File "C:\Users\HP\anaconda3\lib\site-packages\requests\api.py", line 61, in request
    return session.request(method=method, url=url, **kwargs)
  File "C:\Users\HP\anaconda3\lib\site-packages\requests\sessions.py", line 542, in request
    resp = self.send(prep, **send_kwargs)
  File "C:\Users\HP\anaconda3\lib\site-packages\requests\sessions.py", line 655, in send
    r = adapter.send(request, **kwargs)
  File "C:\Users\HP\anaconda3\lib\site-packages\requests\adapters.py", line 516, in send
    raise ConnectionError(e, request=request)
requests.exceptions.ConnectionError: HTTPSConnectionPool(host='api.wandb.ai', port=443): Max retries exceeded with url: /graphql (Caused by NewConnectionError('<urllib3.connection.HTTPSConnection object at 0x00000233B08CF220>: Failed to establish a new connection: [Errno 11001] getaddrinfo failed'))
2021-09-15 18:04:45,275 DEBUG   HandlerThread:6500 [handler.py:handle_request():126] handle_request: shutdown
2021-09-15 18:04:45,275 INFO    HandlerThread:6500 [handler.py:finish():683] shutting down handler
2021-09-15 18:04:45,923 INFO    WriterThread:6500 [datastore.py:close():281] close: F:\5th sem project\wandb\run-20210915_180410-3jtn7q86\run-3jtn7q86.wandb
2021-09-15 18:09:06,308 INFO    SenderThread:6500 [dir_watcher.py:__init__():169] watching files in: F:\5th sem project\wandb\run-20210915_180410-3jtn7q86\files
2021-09-15 18:09:06,308 INFO    SenderThread:6500 [sender.py:_start_run_threads():740] run started: 3jtn7q86 with start time 1631709250
2021-09-15 18:09:06,309 INFO    SenderThread:6500 [sender.py:finish():979] shutting down sender
2021-09-15 18:09:06,309 INFO    SenderThread:6500 [dir_watcher.py:finish():283] shutting down directory watcher
2021-09-15 18:09:07,308 INFO    SenderThread:6500 [dir_watcher.py:finish():313] scan: F:\5th sem project\wandb\run-20210915_180410-3jtn7q86\files
2021-09-15 18:09:07,309 INFO    SenderThread:6500 [dir_watcher.py:finish():327] scan save: F:\5th sem project\wandb\run-20210915_180410-3jtn7q86\files\config.yaml config.yaml
2021-09-15 18:09:07,310 INFO    SenderThread:6500 [file_pusher.py:finish():177] shutting down file pusher
2021-09-15 18:09:07,310 INFO    SenderThread:6500 [file_pusher.py:join():182] waiting for file pusher
2021-09-15 18:09:08,939 INFO    Thread-10 :6500 [upload_job.py:push():137] Uploaded file F:\5th sem project\wandb\run-20210915_180410-3jtn7q86\files\config.yaml
2021-09-15 18:09:10,025 INFO    MainThread:6500 [internal.py:handle_exit():76] Internal process exited
