2021-08-17 18:21:09,124 INFO    MainThread:10752 [wandb_setup.py:_flush():69] setting env: {}
2021-08-17 18:21:09,125 INFO    MainThread:10752 [wandb_setup.py:_flush():69] setting login settings: {}
2021-08-17 18:21:09,125 ERROR   MainThread:10752 [wandb_setup.py:_flush():69] error
Traceback (most recent call last):
  File "C:\Users\HP\anaconda3\lib\site-packages\wandb\sdk\wandb_init.py", line 772, in init
    wi.setup(kwargs)
  File "C:\Users\HP\anaconda3\lib\site-packages\wandb\sdk\wandb_init.py", line 161, in setup
    wandb_login._login(anonymous=anonymous, force=force, _disable_warning=True)
  File "C:\Users\HP\anaconda3\lib\site-packages\wandb\sdk\wandb_login.py", line 235, in _login
    wlogin.prompt_api_key()
  File "C:\Users\HP\anaconda3\lib\site-packages\wandb\sdk\wandb_login.py", line 159, in prompt_api_key
    key = apikey.prompt_api_key(
  File "C:\Users\HP\anaconda3\lib\site-packages\wandb\sdk\lib\apikey.py", line 121, in prompt_api_key
    write_key(settings, key, api=api)
  File "C:\Users\HP\anaconda3\lib\site-packages\wandb\sdk\lib\apikey.py", line 206, in write_key
    raise ValueError("API key must be 40 characters long, yours was %s" % len(key))
ValueError: API key must be 40 characters long, yours was 3
2021-08-17 18:21:09,133 INFO    MainThread:10752 [wandb_setup.py:_flush():69] setting login settings: {}
2021-08-17 18:21:09,133 INFO    MainThread:10752 [wandb_setup.py:_flush():69] setting login settings: {}
2021-08-17 18:21:09,133 INFO    MainThread:10752 [wandb_setup.py:_flush():69] setting login settings: {}
2021-08-17 18:21:09,133 INFO    MainThread:10752 [wandb_setup.py:_flush():69] setting login settings: {'api_key': 'f8fbe881da2ae3838d0538510c9c4f5bd721e3e8'}
2021-08-17 18:21:09,134 INFO    MainThread:10752 [wandb_init.py:_log_setup():342] Logging user logs to F:\5th sem project\wandb\run-20210817_182109-pgkz7f3u\logs\debug.log
2021-08-17 18:21:09,134 INFO    MainThread:10752 [wandb_init.py:_log_setup():343] Logging internal logs to F:\5th sem project\wandb\run-20210817_182109-pgkz7f3u\logs\debug-internal.log
2021-08-17 18:21:09,135 INFO    MainThread:10752 [wandb_init.py:_jupyter_setup():294] configuring jupyter hooks <wandb.sdk.wandb_init._WandbInit object at 0x000001DB5BF98EB0>
2021-08-17 18:21:09,136 INFO    MainThread:10752 [wandb_init.py:init():375] calling init triggers
2021-08-17 18:21:09,136 INFO    MainThread:10752 [wandb_init.py:init():380] wandb.init called with sweep_config: {}
config: {}
2021-08-17 18:21:09,136 INFO    MainThread:10752 [wandb_init.py:init():424] starting backend
2021-08-17 18:21:09,136 INFO    MainThread:10752 [backend.py:_multiprocessing_setup():70] multiprocessing start_methods=spawn, using: spawn
2021-08-17 18:21:09,144 INFO    MainThread:10752 [backend.py:ensure_launched():135] starting backend process...
2021-08-17 18:21:09,435 INFO    MainThread:10752 [backend.py:ensure_launched():139] started backend process with pid: 17344
2021-08-17 18:21:09,436 INFO    MainThread:10752 [wandb_init.py:init():429] backend started and connected
2021-08-17 18:21:09,438 INFO    MainThread:10752 [wandb_run.py:_label_probe_notebook():798] probe notebook
2021-08-17 18:21:09,441 INFO    MainThread:10752 [wandb_run.py:_label_probe_notebook():805] Unable to probe notebook: 'NoneType' object has no attribute 'get'
2021-08-17 18:21:09,441 INFO    MainThread:10752 [wandb_init.py:init():477] updated telemetry
2021-08-17 18:21:09,443 INFO    MainThread:10752 [wandb_init.py:init():500] communicating current version
2021-08-17 18:21:14,444 INFO    MainThread:10752 [wandb_init.py:init():513] communicating run to backend with 30 second timeout
2021-08-17 18:21:19,444 INFO    MainThread:10752 [wandb_init.py:init():540] starting run threads in backend
2021-08-17 18:21:24,473 INFO    MainThread:10752 [wandb_run.py:_console_start():1584] atexit reg
2021-08-17 18:21:24,492 INFO    MainThread:10752 [wandb_run.py:_redirect():1458] redirect: SettingsConsole.WRAP
2021-08-17 18:21:24,493 INFO    MainThread:10752 [wandb_run.py:_redirect():1495] Wrapping output streams.
2021-08-17 18:21:24,504 INFO    MainThread:10752 [wandb_run.py:_redirect():1519] Redirects installed.
2021-08-17 18:21:24,504 INFO    MainThread:10752 [wandb_init.py:init():565] run started, returning control to user process
2021-08-17 18:21:24,505 INFO    MainThread:10752 [wandb_config.py:__setitem__():141] config set epochs = 50 - <bound method Run._config_callback of <wandb.sdk.wandb_run.Run object at 0x000001DB5C00A550>>
2021-08-17 18:21:24,505 INFO    MainThread:10752 [wandb_run.py:_config_callback():826] config_cb epochs 50 None
2021-08-17 18:21:24,876 INFO    MainThread:10752 [wandb_init.py:_pause_backend():256] pausing backend
2021-08-17 18:21:24,876 INFO    MainThread:10752 [jupyter.py:save_ipynb():284] not saving jupyter notebook
2021-08-17 18:21:41,821 INFO    MainThread:10752 [wandb_init.py:_resume_backend():265] resuming backend
2021-08-17 18:21:41,979 INFO    MainThread:10752 [wandb_setup.py:_flush():69] setting env: {}
2021-08-17 18:21:41,979 INFO    MainThread:10752 [wandb_setup.py:_flush():69] setting login settings: {}
2021-08-17 18:21:41,980 ERROR   MainThread:10752 [wandb_setup.py:_flush():69] error
Traceback (most recent call last):
  File "C:\Users\HP\anaconda3\lib\site-packages\wandb\sdk\wandb_init.py", line 772, in init
    wi.setup(kwargs)
  File "C:\Users\HP\anaconda3\lib\site-packages\wandb\sdk\wandb_init.py", line 161, in setup
    wandb_login._login(anonymous=anonymous, force=force, _disable_warning=True)
  File "C:\Users\HP\anaconda3\lib\site-packages\wandb\sdk\wandb_login.py", line 235, in _login
    wlogin.prompt_api_key()
  File "C:\Users\HP\anaconda3\lib\site-packages\wandb\sdk\wandb_login.py", line 159, in prompt_api_key
    key = apikey.prompt_api_key(
  File "C:\Users\HP\anaconda3\lib\site-packages\wandb\sdk\lib\apikey.py", line 121, in prompt_api_key
    write_key(settings, key, api=api)
  File "C:\Users\HP\anaconda3\lib\site-packages\wandb\sdk\lib\apikey.py", line 206, in write_key
    raise ValueError("API key must be 40 characters long, yours was %s" % len(key))
ValueError: API key must be 40 characters long, yours was 3
2021-08-17 18:21:42,002 INFO    MainThread:10752 [wandb_setup.py:_flush():69] setting login settings: {}
2021-08-17 18:21:42,002 INFO    MainThread:10752 [wandb_setup.py:_flush():69] setting login settings: {}
2021-08-17 18:21:42,003 INFO    MainThread:10752 [wandb_setup.py:_flush():69] setting login settings: {}
2021-08-17 18:21:42,003 INFO    MainThread:10752 [wandb_setup.py:_flush():69] setting login settings: {'api_key': 'f8fbe881da2ae3838d0538510c9c4f5bd721e3e8'}
2021-08-17 18:21:42,003 INFO    MainThread:10752 [wandb_init.py:_log_setup():342] Logging user logs to F:\5th sem project\wandb\run-20210817_182141-21dhkt0y\logs\debug.log
2021-08-17 18:21:42,004 INFO    MainThread:10752 [wandb_init.py:_log_setup():343] Logging internal logs to F:\5th sem project\wandb\run-20210817_182141-21dhkt0y\logs\debug-internal.log
2021-08-17 18:21:42,005 INFO    MainThread:10752 [wandb_init.py:init():375] calling init triggers
2021-08-17 18:21:42,005 INFO    MainThread:10752 [wandb_init.py:init():380] wandb.init called with sweep_config: {}
config: {}
2021-08-17 18:21:42,006 INFO    MainThread:10752 [wandb_init.py:init():395] re-initializing run, found existing run on stack: pgkz7f3u
2021-08-17 18:21:42,006 INFO    MainThread:10752 [wandb_run.py:finish():1254] finishing run khushal/weather-recognization/pgkz7f3u
