2021-08-18 18:57:19,811 INFO    MainThread:7952 [wandb_setup.py:_flush():69] setting env: {}
2021-08-18 18:57:19,812 INFO    MainThread:7952 [wandb_setup.py:_flush():69] setting login settings: {}
2021-08-18 18:57:19,812 INFO    MainThread:7952 [wandb_init.py:_log_setup():342] Logging user logs to F:\5th sem project\wandb\run-20210818_185719-2xyv9cx7\logs\debug.log
2021-08-18 18:57:19,813 INFO    MainThread:7952 [wandb_init.py:_log_setup():343] Logging internal logs to F:\5th sem project\wandb\run-20210818_185719-2xyv9cx7\logs\debug-internal.log
2021-08-18 18:57:19,814 INFO    MainThread:7952 [wandb_init.py:_jupyter_setup():294] configuring jupyter hooks <wandb.sdk.wandb_init._WandbInit object at 0x000002AB677098B0>
2021-08-18 18:57:19,843 INFO    MainThread:7952 [wandb_init.py:init():375] calling init triggers
2021-08-18 18:57:19,843 INFO    MainThread:7952 [wandb_init.py:init():380] wandb.init called with sweep_config: {}
config: {}
2021-08-18 18:57:19,844 INFO    MainThread:7952 [wandb_init.py:init():395] re-initializing run, found existing run on stack: 3hf6djar
2021-08-18 18:57:19,844 INFO    MainThread:7952 [wandb_run.py:finish():1254] finishing run khushal/weather-recognization/3hf6djar
2021-08-18 18:57:19,844 INFO    MainThread:7952 [wandb_run.py:_atexit_cleanup():1554] got exitcode: 0
2021-08-18 18:57:19,845 INFO    MainThread:7952 [wandb_run.py:_restore():1526] restore
2021-08-18 18:57:27,476 ERROR   MainThread:7952 [wandb_run.py:_atexit_cleanup():1572] Problem finishing run
Traceback (most recent call last):
  File "C:\Users\HP\anaconda3\lib\site-packages\wandb\sdk\wandb_run.py", line 1562, in _atexit_cleanup
    self._on_finish()
  File "C:\Users\HP\anaconda3\lib\site-packages\wandb\sdk\wandb_run.py", line 1698, in _on_finish
    self.history._flush()
  File "C:\Users\HP\anaconda3\lib\site-packages\wandb\sdk\wandb_history.py", line 59, in _flush
    self._callback(row=self._data, step=self._step)
  File "C:\Users\HP\anaconda3\lib\site-packages\wandb\sdk\wandb_run.py", line 885, in _history_callback
    self._backend.interface.publish_history(
  File "C:\Users\HP\anaconda3\lib\site-packages\wandb\sdk\interface\interface.py", line 223, in publish_history
    item.value_json = json_dumps_safer_history(v)  # type: ignore
  File "C:\Users\HP\anaconda3\lib\site-packages\wandb\util.py", line 669, in json_dumps_safer_history
    return json.dumps(obj, cls=WandBHistoryJSONEncoder, **kwargs)
  File "C:\Users\HP\anaconda3\lib\json\__init__.py", line 234, in dumps
    return cls(
  File "C:\Users\HP\anaconda3\lib\json\encoder.py", line 199, in encode
    chunks = self.iterencode(o, _one_shot=True)
  File "C:\Users\HP\anaconda3\lib\json\encoder.py", line 257, in iterencode
    return _iterencode(o, 0)
  File "C:\Users\HP\anaconda3\lib\site-packages\wandb\util.py", line 636, in default
    return json.JSONEncoder.default(self, obj)
  File "C:\Users\HP\anaconda3\lib\json\encoder.py", line 179, in default
    raise TypeError(f'Object of type {o.__class__.__name__} '
TypeError: Object of type DirectoryIterator is not JSON serializable
2021-08-18 18:57:27,485 INFO    MainThread:7952 [wandb_init.py:init():424] starting backend
2021-08-18 18:57:27,486 INFO    MainThread:7952 [backend.py:_multiprocessing_setup():70] multiprocessing start_methods=spawn, using: spawn
2021-08-18 18:57:27,493 INFO    MainThread:7952 [backend.py:ensure_launched():135] starting backend process...
2021-08-18 18:57:27,659 INFO    MainThread:7952 [backend.py:ensure_launched():139] started backend process with pid: 15704
2021-08-18 18:57:27,659 INFO    MainThread:7952 [wandb_init.py:init():429] backend started and connected
2021-08-18 18:57:27,660 INFO    MainThread:7952 [wandb_run.py:_label_probe_notebook():798] probe notebook
2021-08-18 18:57:27,660 INFO    MainThread:7952 [wandb_run.py:_label_probe_notebook():805] Unable to probe notebook: 'NoneType' object has no attribute 'get'
2021-08-18 18:57:27,660 INFO    MainThread:7952 [wandb_init.py:init():477] updated telemetry
2021-08-18 18:57:27,661 INFO    MainThread:7952 [wandb_init.py:init():500] communicating current version
2021-08-18 18:57:31,821 INFO    MainThread:7952 [wandb_init.py:init():505] got version response 
2021-08-18 18:57:31,821 INFO    MainThread:7952 [wandb_init.py:init():513] communicating run to backend with 30 second timeout
2021-08-18 18:57:32,476 INFO    MainThread:7952 [wandb_init.py:init():540] starting run threads in backend
2021-08-18 18:57:37,498 INFO    MainThread:7952 [wandb_run.py:_console_start():1584] atexit reg
2021-08-18 18:57:37,501 INFO    MainThread:7952 [wandb_run.py:_redirect():1458] redirect: SettingsConsole.WRAP
2021-08-18 18:57:37,501 INFO    MainThread:7952 [wandb_run.py:_redirect():1495] Wrapping output streams.
2021-08-18 18:57:37,505 INFO    MainThread:7952 [wandb_run.py:_redirect():1519] Redirects installed.
2021-08-18 18:57:37,505 INFO    MainThread:7952 [wandb_init.py:init():565] run started, returning control to user process
2021-08-18 18:57:37,506 INFO    MainThread:7952 [wandb_config.py:__setitem__():141] config set epochs = 50 - <bound method Run._config_callback of <wandb.sdk.wandb_run.Run object at 0x000002AB561FE310>>
2021-08-18 18:57:37,506 INFO    MainThread:7952 [wandb_run.py:_config_callback():826] config_cb epochs 50 None
2021-08-18 18:57:37,739 INFO    MainThread:7952 [wandb_init.py:_pause_backend():256] pausing backend
2021-08-18 18:57:37,739 INFO    MainThread:7952 [jupyter.py:save_ipynb():284] not saving jupyter notebook
2021-08-18 18:59:43,969 INFO    MainThread:7952 [wandb_init.py:_resume_backend():265] resuming backend
2021-08-18 18:59:44,068 INFO    MainThread:7952 [wandb_setup.py:_flush():69] setting env: {}
2021-08-18 18:59:44,069 INFO    MainThread:7952 [wandb_setup.py:_flush():69] setting login settings: {}
2021-08-18 18:59:44,069 INFO    MainThread:7952 [wandb_init.py:_log_setup():342] Logging user logs to F:\5th sem project\wandb\run-20210818_185943-1d91a8ct\logs\debug.log
2021-08-18 18:59:44,070 INFO    MainThread:7952 [wandb_init.py:_log_setup():343] Logging internal logs to F:\5th sem project\wandb\run-20210818_185943-1d91a8ct\logs\debug-internal.log
2021-08-18 18:59:44,071 INFO    MainThread:7952 [wandb_init.py:init():375] calling init triggers
2021-08-18 18:59:44,071 INFO    MainThread:7952 [wandb_init.py:init():380] wandb.init called with sweep_config: {}
config: {}
2021-08-18 18:59:44,185 INFO    MainThread:7952 [wandb_init.py:init():395] re-initializing run, found existing run on stack: 2xyv9cx7
2021-08-18 18:59:44,185 INFO    MainThread:7952 [wandb_run.py:finish():1254] finishing run khushal/weather-recognization/2xyv9cx7
